Workbook

Sheet Scenario 1
B3: Activity code | C3: Activity description | D3: predecessors | F3: Activity code | G3: optimistic | H3: Most likely | I3: Pessimistic | J3: t(e) | K3: variance | L3: Critical Path
B4: 1 (A) | C4: Initial Project Kick-Off | D4: - | F4: 1 | G4: 1 | H4: 2 | I4: 3 | J4: =ROUND((G4+4*H4+I4)/6,0) -> 2 | K4: =((I4-G4)/6)^2 -> 0.11111111 | L4: ✓ | O4: 0 | Q4: =O4+P6 -> 2 | T4: =Q4 -> 2 | V4: =T4+U6 -> 8 | X4: =V4 -> 8 | Z4: =X4+Y6 -> 13 | AB4: =Z4 -> 13 | AD4: =AB4+AC6 -> 22
B5: 2 (B) | C5: Define Conference Themes & Tracks | D5: 1 | F5: 2 | G5: 4 | H5: 6 | I5: 10 | J5: =ROUND((G5+4*H5+I5)/6,0) -> 6 | K5: =((I5-G5)/6)^2 -> 1 | O5: =O6-O4 -> 0 | P5: A | Q5: =Q6-Q4 -> 0 | T5: =T6-T4 -> 4 | U5: B | V5: =V6-V4 -> 4 | X5: =X6-X4 -> 4 | Y5: F | Z5: =Z6-Z4 -> 4 | AB5: =AB6-AB4 -> 4 | AC5: G | AD5: =AD6-AD4 -> 4 | AR5: =MAX(AP8,AL8) -> 35 | AT5: =AR5+AS7 -> 36
B6: 3 (C ) | C6: Keynote Speaker Identification | D6: 1 | F6: 3 | G6: 3 | H6: 6 | I6: 12 | J6: =FLOOR((G6+4*H6+I6)/6,1) -> 6 | K6: =((I6-G6)/6)^2 -> 2.25 | O6: =Q6-P6 -> 0 | P6: =J4 -> 2 | Q6: =MIN(T6,T10,T14) -> 2 | T6: =V6-U6 -> 6 | U6: =J5 -> 6 | V6: =MIN(AF10,X6) -> 12 | X6: =Z6-Y6 -> 12 | Y6: =J9 -> 5 | Z6: =AB6 -> 17 | AB6: =AD6-AC6 -> 17 | AC6: =J10 -> 9 | AD6: =AN10 -> 26 | AR6: =AR7-AR5 -> 0 | AS6: N | AT6: =AT7-AT5 -> 0
B7: 4 (D) | C7: Venue Booking & Contracting | D7: 1 | F7: 4 | G7: 5 | H7: 8 | I7: 14 | J7: =FLOOR((G7+4*H7+I7)/6,1) -> 8 | K7: =((I7-G7)/6)^2 -> 2.25 | L7: ✓ | AR7: =AT7-AS7 -> 35 | AS7: 1 | AT7: =AR13 -> 36
B8: 5 (E ) | C8: Hybrid Technical Setup | D8: 4 | F8: 5 | G8: 6 | H8: 10 | I8: 16 | J8: =ROUND((G8+4*H8+I8)/6,0) -> 10 | K8: =((I8-G8)/6)^2 -> 2.7777778 | T8: =Q4 -> 2 | V8: =T8+U10 -> 8 | AB8: =V8 -> 8 | AD8: =AB8+AC10 -> 15 | AF8: =MAX(AD8,V4) -> 15 | AH8: =AF8+AG10 -> 22 | AJ8: =AH8 -> 22 | AL8: =AJ8+AK10 -> 34 | AN8: =MAX(Z12,AD4,AP12) -> 26 | AP8: =AN8+AO10 -> 35
B9: 6 (F) | C9: Sponsorship Package Development | D9: 2 | F9: 6 | G9: 3 | H9: 5 | I9: 9 | J9: =ROUND((G9+4*H9+I9)/6,0) -> 5 | K9: =((I9-G9)/6)^2 -> 1 | T9: =T10-T8 -> 1 | U9: C | V9: =V10-V8 -> 1 | AB9: =AB10-AB8 -> 1 | AC9: H | AD9: =AD10-AD8 -> 1 | AF9: =AF10-AF8 -> 1 | AG9: I | AH9: =AH10-AH8 -> 1 | AJ9: =AJ10-AJ8 -> 1 | AK9: J | AL9: =AL10-AL8 -> 1 | AN9: =AN10-AN8 -> 0 | AO9: M | AP9: =AP10-AP8 -> 0
B10: 7 (G) | C10: Sponsor Outreach & Negotiation | D10: 6 | F10: 7 | G10: 5 | H10: 9 | I10: 18 | J10: =FLOOR((G10+4*H10+I10)/6,1) -> 9 | K10: =((I10-G10)/6)^2 -> 4.6944444 | T10: =V10-U10 -> 3 | U10: =J6 -> 6 | V10: =AB10 -> 9 | AB10: =AD10-AC10 -> 9 | AC10: =J11 -> 7 | AD10: =AF10 -> 16 | AF10: =AH10-AG10 -> 16 | AG10: =J12 -> 7 | AH10: =AJ10 -> 23 | AJ10: =AL10-AK10 -> 23 | AK10: =J13 -> 12 | AL10: =AR7 -> 35 | AN10: =AP10-AO10 -> 26 | AO10: =J16 -> 9 | AP10: =AR7 -> 35
B11: 8 (H) | C11: Keynote Speaker Confirmation | D11: 3 | F11: 8 | G11: 4 | H11: 7 | I11: 13 | J11: =FLOOR((G11+4*H11+I11)/6,1) -> 7 | K11: =((I11-G11)/6)^2 -> 2.25 | AR11: =AT5 -> 36 | AT11: =AR11+AS13 -> 41
B12: 9 (I) | C12: Marketing Plan Development | D12: 2, 8 | F12: 9 | G12: 4 | H12: 7 | I12: 11 | J12: =ROUND((G12+4*H12+I12)/6,0) -> 7 | K12: =((I12-G12)/6)^2 -> 1.3611111 | T12: =Q4 -> 2 | V12: =T12+U14 -> 10 | X12: =V12 -> 10 | Z12: =X12+Y14 -> 20 | AJ12: =V12 -> 10 | AL12: =AJ12+AK14 -> 19 | AN12: =AL12 -> 19 | AP12: =AN12+AO14 -> 26 | AR12: =AR13-AR11 -> 0 | AS12: O | AT12: =AT13-AT11 -> 0
B13: 10( J) | C13: Promotional Campaign Execution | D13: 9 | F13: 10 | G13: 7 | H13: 12 | I13: 20 | J13: =FLOOR((G13+4*H13+I13)/6,1) -> 12 | K13: =((I13-G13)/6)^2 -> 4.6944444 | T13: =T14-T12 -> 0 | U13: D | V13: =V14-V12 -> 0 | X13: =X14-X12 -> 6 | Y13: E | Z13: =Z14-Z12 -> 6 | AJ13: =AJ14-AJ12 -> 0 | AK13: K | AL13: =AL14-AL12 -> 0 | AN13: =AN14-AN12 -> 0 | AO13: L | AP13: =AP14-AP12 -> 0 | AR13: =AT13-AS13 -> 36 | AS13: 5 | AT13: =AT11 -> 41
B14: 11 (K) | C14: Catering & Layout Planning | D14: 4 | F14: 11 | G14: 6 | H14: 9 | I14: 14 | J14: =ROUND((G14+4*H14+I14)/6,0) -> 9 | K14: =((I14-G14)/6)^2 -> 1.7777778 | L14: ✓ | T14: =V14-U14 -> 2 | U14: =J7 -> 8 | V14: =MIN(AJ14,X14) -> 10 | X14: =Z14-Y14 -> 16 | Y14: =J8 -> 10 | Z14: =AN10 -> 26 | AJ14: =AL14-AK14 -> 10 | AK14: =J14 -> 9 | AL14: =AN14 -> 19 | AN14: =AP14-AO14 -> 19 | AO14: =J15 -> 7 | AP14: =AN10 -> 26
B15: 12 (L) | C15: Volunteer Recruitment & Training | D15: 11 | F15: 12 | G15: 4 | H15: 7 | I15: 13 | J15: =FLOOR((G15+4*H15+I15)/6,1) -> 7 | K15: =((I15-G15)/6)^2 -> 2.25 | L15: ✓
B16: 13 (M) | C16: On-Site Logistics Preparation | D16: 5, 7, 12 | F16: 13 | G16: 5 | H16: 9 | I16: 15 | J16: =ROUND((G16+4*H16+I16)/6,0) -> 9 | K16: =((I16-G16)/6)^2 -> 2.7777778 | L16: ✓
B17: 14 (N) | C17: Conference Delivery Day | D17: 13, 10 | F17: 14 | G17: 1 | H17: 1 | I17: 1 | J17: =ROUND((G17+4*H17+I17)/6,0) -> 1 | K17: =((I17-G17)/6)^2 -> 0 | L17: ✓
B18: 15 (O) | C18: Post-Event Feedback & Reporting | D18: 14 | F18: 15 | G18: 3 | H18: 5 | I18: 8 | J18: =ROUND((G18+4*H18+I18)/6,0) -> 5 | K18: =((I18-G18)/6)^2 -> 0.69444444 | L18: ✓
H25: Mean | I25: Probability
H26: 44 | I26: =_xlfn.NORM.DIST($K$39,H26,$C$38,TRUE) -> 0.62492703
B27: Activity Code | C27: critical activities | D27: tc(e) | E27: variance | H27: 43 | I27: =_xlfn.NORM.DIST($K$39,H27,$C$38,TRUE) -> 0.73790301
B28: 1 | C28: Initial Project Kick-Off | D28: =VLOOKUP(C28,C4:J18,8,0) -> 2 | E28: =VLOOKUP(C28,C4:K18,9,0) -> 0.11111111 | H28: 42 | I28: =_xlfn.NORM.DIST($K$39,H28,$C$38,TRUE) -> 0.83029731
B29: 4 | C29: Venue Booking & Contracting | D29: =VLOOKUP(C29,C5:J19,8,0) -> 8 | E29: =VLOOKUP(C29,C5:K19,9,0) -> 2.25 | H29: 41 | I29: =_xlfn.NORM.DIST($K$39,H29,$C$38,TRUE) -> 0.89863067
B30: 11 | C30: Catering & Layout Planning | D30: =VLOOKUP(C30,C6:J25,8,0) -> 9 | E30: =VLOOKUP(C30,C6:K25,9,0) -> 1.7777778 | H30: 40 | I30: =_xlfn.NORM.DIST($K$39,H30,$C$38,TRUE) -> 0.94433401
B31: 12 | C31: Volunteer Recruitment & Training | D31: =VLOOKUP(C31,C7:J26,8,0) -> 7 | E31: =VLOOKUP(C31,C7:K26,9,0) -> 2.25 | H31: 39 | I31: =_xlfn.NORM.DIST($K$39,H31,$C$38,TRUE) -> 0.97197725
B32: 13 | C32: On-Site Logistics Preparation | D32: =VLOOKUP(C32,C8:J27,8,0) -> 9 | E32: =VLOOKUP(C32,C8:K27,9,0) -> 2.7777778 | H32: 38 | I32: =_xlfn.NORM.DIST($K$39,H32,$C$38,TRUE) -> 0.98709732
B33: 14 | C33: Conference Delivery Day | D33: =VLOOKUP(C33,C9:J28,8,0) -> 1 | E33: =VLOOKUP(C33,C9:K28,9,0) -> 0 | H33: 36 | I33: =_xlfn.NORM.DIST($K$39,H33,$C$38,TRUE) -> 0.99792168
B34: 15 | C34: Post-Event Feedback & Reporting | D34: =VLOOKUP(C34,C10:J29,8,0) -> 5 | E34: =VLOOKUP(C34,C10:K29,9,0) -> 0.69444444
C35: SUM | D35: =SUM(D28:D34) -> 41 | E35: =SUM(E28:E34) -> 9.8611111
B37: Expected project duration | C37: =D35 -> 41
B38: project standard deviation | C38: =SQRT(E35) -> 3.1402406
G39: SCHEDULED PROJECT DURATION | K39: 45
B40: chance of this project | C40: =_xlfn.NORM.DIST(K39,C37,C38,TRUE) -> 0.89863067
B42: chance | C42: 0.95
B43: Project Average duration must be | C43: =H31 -> 39

Sheet Scenario 2 & 3 Crashing
C4: 0 | E4: =C4+D6 -> 2 | H4: =E4 -> 2 | J4: =H4+I6 -> 8 | L4: =J4 -> 8 | N4: =L4+M6 -> 12 | P4: =N4 -> 12 | R4: =P4+Q6 -> 19
C5: =C6-C4 -> 0 | D5: A | E5: =E6-E4 -> 0 | H5: =H6-H4 -> 1 | I5: B | J5: =J6-J4 -> 1 | L5: =L6-L4 -> 1 | M5: F | N5: =N6-N4 -> 1 | P5: =P6-P4 -> 1 | Q5: G | R5: =R6-R4 -> 1 | AF5: =MAX(AD8,Z8) -> 26 | AH5: =AF5+AG7 -> 27
C6: =E6-D6 -> 0 | D6: 2 | E6: =MIN(H6,H10,H14) -> 2 | H6: =J6-I6 -> 3 | I6: 6 | J6: =MIN(T10,L6) -> 9 | L6: =N6-M6 -> 9 | M6: 4 | N6: =P6 -> 13 | P6: =R6-Q6 -> 13 | Q6: 7 | R6: =AB10 -> 20 | AF6: =AF7-AF5 -> 0 | AG6: N | AH6: =AH7-AH5 -> 0
AF7: =AH7-AG7 -> 26 | AG7: 1 | AH7: =AF13 -> 27
H8: =E4 -> 2 | J8: =H8+I10 -> 6 | P8: =J8 -> 6 | R8: =P8+Q10 -> 11 | T8: =MAX(R8,J4) -> 11 | V8: =T8+U10 -> 17 | X8: =V8 -> 17 | Z8: =X8+Y10 -> 26 | AB8: =MAX(N12,R4,AD12) -> 19 | AD8: =AB8+AC10 -> 25
H9: =H10-H8 -> 0 | I9: C | J9: =J10-J8 -> 0 | P9: =P10-P8 -> 0 | Q9: H | R9: =R10-R8 -> 0 | T9: =T10-T8 -> 0 | U9: I | V9: =V10-V8 -> 0 | X9: =X10-X8 -> 0 | Y9: J | Z9: =Z10-Z8 -> 0 | AB9: =AB10-AB8 -> 1 | AC9: M | AD9: =AD10-AD8 -> 1
H10: =J10-I10 -> 2 | I10: 4 | J10: =P10 -> 6 | P10: =R10-Q10 -> 6 | Q10: 5 | R10: =T10 -> 11 | T10: =V10-U10 -> 11 | U10: 6 | V10: =X10 -> 17 | X10: =Z10-Y10 -> 17 | Y10: 9 | Z10: =AF7 -> 26 | AB10: =AD10-AC10 -> 20 | AC10: 6 | AD10: =AF7 -> 26
AF11: =AH5 -> 27 | AH11: =AF11+AG13 -> 31
H12: =E4 -> 2 | J12: =H12+I14 -> 7 | L12: =J12 -> 7 | N12: =L12+M14 -> 17 | X12: =J12 -> 7 | Z12: =X12+Y14 -> 14 | AB12: =Z12 -> 14 | AD12: =AB12+AC14 -> 19 | AF12: =AF13-AF11 -> 0 | AG12: O | AH12: =AH13-AH11 -> 0
H13: =H14-H12 -> 1 | I13: D | J13: =J14-J12 -> 1 | L13: =L14-L12 -> 3 | M13: E | N13: =N14-N12 -> 3 | X13: =X14-X12 -> 1 | Y13: K | Z13: =Z14-Z12 -> 1 | AB13: =AB14-AB12 -> 1 | AC13: L | AD13: =AD14-AD12 -> 1 | AF13: =AH13-AG13 -> 27 | AG13: 4 | AH13: =AH11 -> 31
H14: =J14-I14 -> 3 | I14: 5 | J14: =MIN(X14,L14) -> 8 | L14: =N14-M14 -> 10 | M14: 10 | N14: =AB10 -> 20 | X14: =Z14-Y14 -> 8 | Y14: 7 | Z14: =AB14 -> 15 | AB14: =AD14-AC14 -> 15 | AC14: 5 | AD14: =AB10 -> 20
Z21: Indirect Cost is | AB21: 90000 | AC21: with | AD21: 4200 | AE21: reduction for one time unit shorten
Z22: Activity ID | AA22: Slope ($) | AB22: Max crash time | AF22: Direct Cost
AF23: Normal | AH23: Crash
AF24: Time | AG24: Cost | AH24: Time | AI24: Cost
Z25: A | AA25: - | AB25: 0 | AF25: ='Scenario 1'!J4 -> 2 | AG25: 3000 | AH25: 0 | AI25: 0
Z26: B | AA26: 4000 | AB26: 2 | AF26: ='Scenario 1'!J5 -> 6 | AG26: 8000 | AH26: 2 | AI26: 4000
Z27: C | AA27: 5000 | AB27: 2 | AC27: 1 | AD27: 0 | AF27: ='Scenario 1'!J6 -> 6 | AG27: 10000 | AH27: 2 | AI27: 5000
Z28: D | AA28: 6000 | AB28: 3 | AC28: 2 | AD28: 1 | AE28: 0 | AF28: ='Scenario 1'!J7 -> 8 | AG28: 18000 | AH28: 3 | AI28: 6000
Z29: E | AA29: 7000 | AB29: 3 | AF29: ='Scenario 1'!J8 -> 10 | AG29: 22000 | AH29: 3 | AI29: 7000
Z30: F | AA30: 3000 | AB30: 1 | AC30: 0 | AF30: ='Scenario 1'!J9 -> 5 | AG30: 6000 | AH30: 1 | AI30: 3000
Z31: G | AA31: 4000 | AB31: 3 | AC31: 2 | AD31: 1 | AF31: ='Scenario 1'!J10 -> 9 | AG31: 12000 | AH31: 3 | AI31: 4000
Z32: H | AA32: 6000 | AB32: 2 | AC32: 1 | AD32: 0 | AF32: ='Scenario 1'!J11 -> 7 | AG32: 14000 | AH32: 2 | AI32: 6000
Z33: I | AA33: 4000 | AB33: 1 | AC33: 0 | AF33: ='Scenario 1'!J12 -> 7 | AG33: 9000 | AH33: 1 | AI33: 4000
Z34: J | AA34: 5000 | AB34: 3 | AC34: 2 | AD34: 1 | AE34: 0 | AF34: ='Scenario 1'!J13 -> 12 | AG34: 15000 | AH34: 3 | AI34: 5000
Z35: K | AA35: 4000 | AB35: 2 | AC35: 1 | AD35: 0 | AF35: ='Scenario 1'!J14 -> 9 | AG35: 11000 | AH35: 2 | AI35: 4000
Z36: L | AA36: 3500 | AB36: 2 | AC36: 1 | AD36: 0 | AF36: ='Scenario 1'!J15 -> 7 | AG36: 8000 | AH36: 2 | AI36: 3500
Z37: M | AA37: 6000 | AB37: 3 | AC37: 2 | AD37: 1 | AE37: 0 | AF37: ='Scenario 1'!J16 -> 9 | AG37: 20000 | AH37: 3 | AI37: 6000
Z38: N | AA38: - | AB38: 0 | AF38: ='Scenario 1'!J17 -> 1 | AG38: 30000 | AH38: 0 | AI38: 0
Z39: O | AA39: 2000 | AB39: 1 | AC39: 0 | AF39: ='Scenario 1'!J18 -> 5 | AG39: 6000 | AH39: 1 | AI39: 2000
G42: Path duration
B44: Paths/Iteration | G44: I0 | I44: I1 | K44: I2 | M44: I3 | O44: I4 | Q44: I5 | S44: I6 | U44: I7 | W44: I8 | Y44: I9 | AA44: I10
B45: ABFGMNO | G45: 37 | I45: 37 | K45: 37 | M45: 37 | O45: 37 | Q45: 35 | S45: 34 | U45: 33 | W45: 33 | Y45: 32 | AA45: =$D$6+$I$6+$M$6+$Q$6+$AC$10+$AG$7+$AG$13 -> 30
B46: ABIJNO | G46: 33 | I46: 33 | K46: 32 | M46: 31 | O46: 30 | Q46: 29 | S46: 29 | U46: 29 | W46: 29 | Y46: 29 | AA46: =$D$6+$I$6+$U$10+$Y$10+$AG$7+$AG$13 -> 28
B47: ACHIJNO | G47: 40 | I47: 40 | K47: 39 | M47: 38 | O47: 37 | Q47: 36 | S47: 35 | U47: 34 | W47: 33 | Y47: 32 | AA47: =$D$6+$I$10+$Q$10+$U$10+$Y$10+$AG$7+$AG$13 -> 31
B48: ADEMNO | G48: 35 | I48: 35 | K48: 35 | M48: 35 | O48: 35 | Q48: 34 | S48: 33 | U48: 32 | W48: 31 | Y48: 30 | AA48: =$D$6+$I$14+$M$14+$AC$10+$AG$7+$AG$13 -> 28
B49: ADKLMNO | G49: 41 | I49: 40 | K49: 39 | M49: 38 | O49: 37 | Q49: 36 | S49: 35 | U49: 34 | W49: 33 | Y49: 32 | AA49: =$D$6+$I$14+$Y$14+$AC$14+$AC$10+$AG$7+$AG$13 -> 30
Z54: Project duration | AA54: Crashed activities | AB54: Crash cost | AC54: direct cost | AD54: Indirect cost | AE54: Total cost
Y55: I0 | Z55: 41 | AA55: - | AB55: - | AC55: =SUM(AG25:AG39) -> 192000 | AD55: =AB21 -> 90000 | AE55: =AC55+AD55 -> 282000
Y56: I1 | Z56: 40 | AA56: L | AB56: =AA36 -> 3500 | AC56: =AC55+AB56 -> 195500 | AD56: =AD55-$AD$21 -> 85800 | AE56: =AC56+AD56 -> 281300
...

Sheet Exercise 2
B2: Time in Workdays
B3: # | C3: Task Name | D3: Optimistic Dur. | E3: Most Likely Dur. | F3: Pessimistic Dur. | G3: Immediate Predecessor | H3: Critical Path | J3: T(e) | K3: variance
B4: 1 | C4: AET DATA CENTER MIGRATION | D4: 54 | E4: 68 | F4: 92 | J4: =(D4+4*E4+F4)/6 -> 69.666667 | K4: =((F4-D4)/6)^2 -> 40.111111 | M4: Expected project duration | N4: =J5+J12+J13+J17+J19+J24+J27+J28+J29+J30+J31 -> 69 | O4: =SQRT(K5+K12+K13+K17+K19+K24+K27+K28+K29+K30+K31) -> 2.4152295
B5: 2 | C5: Team meeting | D5: 0.5 | E5: 1 | F5: 1.5 | H5: ✓ | J5: =(D5+4*E5+F5)/6 -> 1 | K5: =((F5-D5)/6)^2 -> 0.027777778 | M5: project standard deviation | N5: 2.42 | P5: 1. Based on these estimates and the resultant expected project duration of 69 days, the executive committee wants to know what is the probability of completing the project before a scheduled time (TS) of 68 days?
B6: 3 | C6: Hire contractors | D6: 6 | E6: 7 | F6: 8 | G6: 2 | J6: =(D6+4*E6+F6)/6 -> 7 | K6: =((F6-D6)/6)^2 -> 0.11111111
B7: 4 | C7: Network design | D7: 12 | E7: 14 | F7: 16 | G7: 2 | J7: =(D7+4*E7+F7)/6 -> 14 | K7: =((F7-D7)/6)^2 -> 0.44444444 | M7: Scheduled duration | N7: 68
B8: 5 | C8: Ventilation system | D8: — | E8: — | F8: — | G8: — | J8: — | K8: —
B9: 6 | C9: Order ventilation system | D9: 18 | E9: 21 | F9: 30 | G9: 2 | J9: =(D9+4*E9+F9)/6 -> 22 | K9: =((F9-D9)/6)^2 -> 4 | M9: chance of this project | N9: =_xlfn.NORM.DIST(N7,N4,N5,TRUE) -> 0.33972157
B10: 7 | C10: Install ventilation system | D10: 5 | E10: 7 | F10: 9 | G10: 6 | J10: =(D10+4*E10+F10)/6 -> 7 | K10: =((F10-D10)/6)^2 -> 0.44444444
B11: 8 | C11: New racks | D11: — | E11: — | F11: — | G11: — | J11: — | K11: —
B12: 9 | C12: Order new racks | D12: 13 | E12: 14 | F12: 21 | G12: 2 | H12: ✓ | J12: =(D12+4*E12+F12)/6 -> 15 | K12: =((F12-D12)/6)^2 -> 1.7777778 | M12: 93 percent chance of completion within 68 days.
B13: 10 | C13: Install racks | D13: 17 | E13: 21 | F13: 25 | G13: 9 | H13: ✓ | J13: =(D13+4*E13+F13)/6 -> 21 | K13: =((F13-D13)/6)^2 -> 1.7777778
B14: 11 | C14: Power supplies and cables | D14: — | E14: — | F14: — | G14: — | J14: — | K14: — | M14: Probablity | N14: 0.93
B15: 12 | C15: Order power supplies & cables | D15: 6 | E15: 7 | F15: 8 | G15: 2 | J15: =(D15+4*E15+F15)/6 -> 7 | K15: =((F15-D15)/6)^2 -> 0.11111111 | M15: Scheduled duration | N15: 68
B16: 13 | C16: Install power supplies | D16: 5 | E16: 5 | F16: 11 | G16: 12, 16 | J16: =(D16+4*E16+F16)/6 -> 6 | K16: =((F16-D16)/6)^2 -> 1 | P16: 2. The significance of this project has the executive committee very concerned. The committee has decided that more analysis of the duration of each activity is needed. Prior to conducting that effort, they asked Brian to calculate what the expected project duration would have to be to ensure a 93 percent chance of completion within 68 days.
B17: 14 | C17: Install cables | D17: 6 | E17: 8 | F17: 10 | G17: 12, 16 | H17: ✓ | J17: =(D17+4*E17+F17)/6 -> 8 | K17: =((F17-D17)/6)^2 -> 0.44444444 | M17: Expected project duration | N17: Probablity
B18: 15 | C18: Renovation of data centre | D18: 19 | E18: 20 | F18: 27 | G18: 3, 4 | J18: =(D18+4*E18+F18)/6 -> 21 | K18: =((F18-D18)/6)^2 -> 1.7777778 | M18: 68 | N18: =_xlfn.NORM.DIST($N$15,M18,$N$5,TRUE) -> 0.5
B19: 16 | C19: City inspection | D19: 1 | E19: 2 | F19: 3 | G19: 3, 7, 10 | H19: ✓ | J19: =(D19+4*E19+F19)/6 -> 2 | K19: =((F19-D19)/6)^2 -> 0.11111111 | M19: 67 | N19: =_xlfn.NORM.DIST($N$15,M19,$N$5,TRUE) -> 0.66027843
B20: 17 | C20: Switchover Meetings | D20: — | E20: — | F20: — | G20: — | J20: — | K20: — | M20: 66 | N20: =_xlfn.NORM.DIST($N$15,M20,$N$5,TRUE) -> 0.79572451
B21: 18 | C21: Facilities | D21: 7 | E21: 8 | F21: 9 | G21: 14 | J21: =(D21+4*E21+F21)/6 -> 8 | K21: =((F21-D21)/6)^2 -> 0.11111111 | M21: 65 | N21: =_xlfn.NORM.DIST($N$15,M21,$N$5,TRUE) -> 0.89245115
B22: 19 | C22: Operations/systems | D22: 5 | E22: 7 | F22: 9 | G22: 14 | J22: =(D22+4*E22+F22)/6 -> 7 | K22: =((F22-D22)/6)^2 -> 0.44444444 | M22: 64 | N22: =_xlfn.NORM.DIST($N$15,M22,$N$5,TRUE) -> 0.95082363
B23: 20 | C23: Operations/telecommunications | D23: 6 | E23: 7 | F23: 8 | G23: 14 | J23: =(D23+4*E23+F23)/6 -> 7 | K23: =((F23-D23)/6)^2 -> 0.11111111 | M23: 63 | N23: =_xlfn.NORM.DIST($N$15,M23,$N$5,TRUE) -> 0.98059122
B24: 21 | C24: Systems & applications | D24: 7 | E24: 7 | F24: 13 | G24: 14 | H24: ✓ | J24: =(D24+4*E24+F24)/6 -> 8 | K24: =((F24-D24)/6)^2 -> 1 | M24: 62 | N24: =_xlfn.NORM.DIST($N$15,M24,$N$5,TRUE) -> 0.99341869
B25: 22 | C25: Customer service | D25: 5 | E25: 6 | F25: 13 | G25: 14 | J25: =(D25+4*E25+F25)/6 -> 7 | K25: =((F25-D25)/6)^2 -> 1.7777778 | M25: 61 | N25: =_xlfn.NORM.DIST($N$15,M25,$N$5,TRUE) -> 0.99808943
B26: 23 | C26: Power check | D26: 0.5 | E26: 1 | F26: 1.5 | G26: 13, 14, 15 | J26: =(D26+4*E26+F26)/6 -> 1 | K26: =((F26-D26)/6)^2 -> 0.027777778
B27: 24 | C27: Install test servers | D27: 5 | E27: 7 | F27: 9 | G27: 2, 3, 18, 19, 20, 21 | H27: ✓ | J27: =(D27+4*E27+F27)/6 -> 7 | K27: =((F27-D27)/6)^2 -> 0.44444444
B28: 25 | C28: Management safety check | D28: 1 | E28: 2 | F28: 3 | G28: 7, 23, 24 | H28: ✓ | J28: =(D28+4*E28+F28)/6 -> 2 | K28: =((F28-D28)/6)^2 -> 0.11111111
B29: 26 | C29: Primary systems check | D29: 1.5 | E29: 2 | F29: 2.5 | G29: 25 | H29: ✓ | J29: =(D29+4*E29+F29)/6 -> 2 | K29: =((F29-D29)/6)^2 -> 0.027777778
B30: 27 | C30: Set date for move | D30: 1 | E30: 1 | F30: 1 | G30: 26 | H30: ✓ | J30: =(D30+4*E30+F30)/6 -> 1 | K30: =((F30-D30)/6)^2 -> 0
B31: 28 | C31: Complete move | D31: 1 | E31: 2 | F31: 3 | G31: 27 | H31: ✓ | J31: =(D31+4*E31+F31)/6 -> 2 | K31: =((F31-D31)/6)^2 -> 0.11111111

Sheet Scenario 4
B3: Activity code | C3: Activity description | D3: predecessors | F3: Activity code | G3: optimistic | H3: Most likely | I3: Pessimistic | J3: t(e) | K3: variance | L3: Critical Path
B4: 1 (A) | C4: Initial Project Kick-Off | D4: - | F4: 1 | G4: 1 | H4: 2 | I4: 3 | J4: =ROUND((G4+4*H4+I4)/6,0) -> 2 | K4: =((I4-G4)/6)^2 -> 0.11111111 | L4: ✓ | O4: 0 | Q4: =O4+P6 -> 2 | T4: =Q4 -> 2 | V4: =T4+U6 -> 8 | X4: =V4 -> 8 | Z4: =X4+Y6 -> 13 | AB4: =Z4 -> 13 | AD4: =AB4+AC6 -> 22
B5: 2 (B) | C5: Define Conference Themes & Tracks | D5: 1 | F5: 2 | G5: 4 | H5: 6 | I5: 10 | J5: =ROUND((G5+4*H5+I5)/6,0) -> 6 | K5: =((I5-G5)/6)^2 -> 1 | O5: =O6-O4 -> 0 | P5: A | Q5: =Q6-Q4 -> 0 | T5: =T6-T4 -> 3 | U5: B | V5: =V6-V4 -> 3 | X5: =X6-X4 -> 3 | Y5: F | Z5: =Z6-Z4 -> 3 | AB5: =AB6-AB4 -> 3 | AC5: G | AD5: =AD6-AD4 -> 3 | AR5: =MAX(AP8,AL8) -> 34 | AT5: =AR5+AS7 -> 35
B6: 3 (C ) | C6: Keynote Speaker Identification | D6: 1 | F6: 3 | G6: 3 | H6: 6 | I6: 12 | J6: =FLOOR((G6+4*H6+I6)/6,1) -> 6 | K6: =((I6-G6)/6)^2 -> 2.25 | L6: ✓ | O6: =Q6-P6 -> 0 | P6: =J4 -> 2 | Q6: =MIN(T6,T10,T14) -> 2 | T6: =V6-U6 -> 5 | U6: =J5 -> 6 | V6: =MIN(AF10,X6) -> 11 | X6: =Z6-Y6 -> 11 | Y6: =J9 -> 5 | Z6: =AB6 -> 16 | AB6: =AD6-AC6 -> 16 | AC6: =J10 -> 9 | AD6: =AN10 -> 25 | AR6: =AR7-AR5 -> 0 | AS6: N | AT6: =AT7-AT5 -> 0
B7: 4 (D) | C7: Venue Booking & Contracting | D7: 1 | F7: 4 | G7: 0 | H7: 1 | I7: 2 | J7: =FLOOR((G7+4*H7+I7)/6,1) -> 1 | K7: =((I7-G7)/6)^2 -> 0.11111111 | AR7: =AT7-AS7 -> 34 | AS7: 1 | AT7: =AR13 -> 35
B8: 5 (E ) | C8: Hybrid Technical Setup | D8: 4 | F8: 5 | G8: 6 | H8: 10 | I8: 16 | J8: =ROUND((G8+4*H8+I8)/6,0) -> 10 | K8: =((I8-G8)/6)^2 -> 2.7777778 | T8: =Q4 -> 2 | V8: =T8+U10 -> 8 | AB8: =V8 -> 8 | AD8: =AB8+AC10 -> 15 | AF8: =MAX(AD8,V4) -> 15 | AH8: =AF8+AG10 -> 22 | AJ8: =AH8 -> 22 | AL8: =AJ8+AK10 -> 34 | AN8: =MAX(Z12,AD4,AP12) -> 22 | AP8: =AN8+AO10 -> 31
B9: 6 (F) | C9: Sponsorship Package Development | D9: 2 | F9: 6 | G9: 3 | H9: 5 | I9: 9 | J9: =ROUND((G9+4*H9+I9)/6,0) -> 5 | K9: =((I9-G9)/6)^2 -> 1 | T9: =T10-T8 -> 0 | U9: C | V9: =V10-V8 -> 0 | AB9: =AB10-AB8 -> 0 | AC9: H | AD9: =AD10-AD8 -> 0 | AF9: =AF10-AF8 -> 0 | AG9: I | AH9: =AH10-AH8 -> 0 | AJ9: =AJ10-AJ8 -> 0 | AK9: J | AL9: =AL10-AL8 -> 0 | AN9: =AN10-AN8 -> 3 | AO9: M | AP9: =AP10-AP8 -> 3
B10: 7 (G) | C10: Sponsor Outreach & Negotiation | D10: 6 | F10: 7 | G10: 5 | H10: 9 | I10: 18 | J10: =FLOOR((G10+4*H10+I10)/6,1) -> 9 | K10: =((I10-G10)/6)^2 -> 4.6944444 | T10: =V10-U10 -> 2 | U10: =J6 -> 6 | V10: =AB10 -> 8 | AB10: =AD10-AC10 -> 8 | AC10: =J11 -> 7 | AD10: =AF10 -> 15 | AF10: =AH10-AG10 -> 15 | AG10: =J12 -> 7 | AH10: =AJ10 -> 22 | AJ10: =AL10-AK10 -> 22 | AK10: =J13 -> 12 | AL10: =AR7 -> 34 | AN10: =AP10-AO10 -> 25 | AO10: =J16 -> 9 | AP10: =AR7 -> 34
B11: 8 (H) | C11: Keynote Speaker Confirmation | D11: 3 | F11: 8 | G11: 4 | H11: 7 | I11: 13 | J11: =FLOOR((G11+4*H11+I11)/6,1) -> 7 | K11: =((I11-G11)/6)^2 -> 2.25 | L11: ✓ | AR11: =AT5 -> 35 | AT11: =AR11+AS13 -> 40
B12: 9 (I) | C12: Marketing Plan Development | D12: 2, 8 | F12: 9 | G12: 4 | H12: 7 | I12: 11 | J12: =ROUND((G12+4*H12+I12)/6,0) -> 7 | K12: =((I12-G12)/6)^2 -> 1.3611111 | L12: ✓ | T12: =Q4 -> 2 | V12: =T12+U14 -> 3 | X12: =V12 -> 3 | Z12: =X12+Y14 -> 13 | AJ12: =V12 -> 3 | AL12: =AJ12+AK14 -> 12 | AN12: =AL12 -> 12 | AP12: =AN12+AO14 -> 19 | AR12: =AR13-AR11 -> 0 | AS12: O | AT12: =AT13-AT11 -> 0
B13: 10( J) | C13: Promotional Campaign Execution | D13: 9 | F13: 10 | G13: 7 | H13: 12 | I13: 20 | J13: =FLOOR((G13+4*H13+I13)/6,1) -> 12 | K13: =((I13-G13)/6)^2 -> 4.6944444 | L13: ✓ | T13: =T14-T12 -> 6 | U13: D | V13: =V14-V12 -> 6 | X13: =X14-X12 -> 12 | Y13: E | Z13: =Z14-Z12 -> 12 | AJ13: =AJ14-AJ12 -> 6 | AK13: K | AL13: =AL14-AL12 -> 6 | AN13: =AN14-AN12 -> 6 | AO13: L | AP13: =AP14-AP12 -> 6 | AR13: =AT13-AS13 -> 35 | AS13: 5 | AT13: =AT11 -> 40
B14: 11 (K) | C14: Catering & Layout Planning | D14: 4 | F14: 11 | G14: 6 | H14: 9 | I14: 14 | J14: =ROUND((G14+4*H14+I14)/6,0) -> 9 | K14: =((I14-G14)/6)^2 -> 1.7777778 | T14: =V14-U14 -> 8 | U14: =J7 -> 1 | V14: =MIN(AJ14,X14) -> 9 | X14: =Z14-Y14 -> 15 | Y14: =J8 -> 10 | Z14: =AN10 -> 25 | AJ14: =AL14-AK14 -> 9 | AK14: =J14 -> 9 | AL14: =AN14 -> 18 | AN14: =AP14-AO14 -> 18 | AO14: =J15 -> 7 | AP14: =AN10 -> 25
B15: 12 (L) | C15: Volunteer Recruitment & Training | D15: 11 | F15: 12 | G15: 4 | H15: 7 | I15: 13 | J15: =FLOOR((G15+4*H15+I15)/6,1) -> 7 | K15: =((I15-G15)/6)^2 -> 2.25
B16: 13 (M) | C16: On-Site Logistics Preparation | D16: 5, 7, 12 | F16: 13 | G16: 5 | H16: 9 | I16: 15 | J16: =ROUND((G16+4*H16+I16)/6,0) -> 9 | K16: =((I16-G16)/6)^2 -> 2.7777778
B17: 14 (N) | C17: Conference Delivery Day | D17: 13, 10 | F17: 14 | G17: 1 | H17: 1 | I17: 1 | J17: =ROUND((G17+4*H17+I17)/6,0) -> 1 | K17: =((I17-G17)/6)^2 -> 0 | L17: ✓
B18: 15 (O) | C18: Post-Event Feedback & Reporting | D18: 14 | F18: 15 | G18: 3 | H18: 5 | I18: 8 | J18: =ROUND((G18+4*H18+I18)/6,0) -> 5 | K18: =((I18-G18)/6)^2 -> 0.69444444 | L18: ✓
H25: Mean | I25: Probability
H26: 44 | I26: =_xlfn.NORM.DIST($K$39,H26,$C$38,TRUE) -> 0.61664493
B27: Activity Code | C27: critical activities | D27: tc(e) | E27: variance | H27: 43 | I27: =_xlfn.NORM.DIST($K$39,H27,$C$38,TRUE) -> 0.72353048
B28: 1 | C28: Initial Project Kick-Off | D28: =VLOOKUP(C28,C4:J18,8,0) -> 2 | E28: =VLOOKUP(C28,C4:K18,9,0) -> 0.11111111 | H28: 42 | I28: =_xlfn.NORM.DIST($K$39,H28,$C$38,TRUE) -> 0.81327853
B29: 3 | C29: Keynote Speaker Identification | D29: =VLOOKUP(C29,C5:J19,8,0) -> 6 | E29: =VLOOKUP(C29,C5:K19,9,0) -> 2.25 | H29: 41 | I29: =_xlfn.NORM.DIST($K$39,H29,$C$38,TRUE) -> 0.88233167
B30: 8 | C30: Keynote Speaker Confirmation | D30: =VLOOKUP(C30,C6:J25,8,0) -> 7 | E30: =VLOOKUP(C30,C6:K25,9,0) -> 2.25 | H30: 40 | I30: =_xlfn.NORM.DIST($K$39,H30,$C$38,TRUE) -> 0.93101652
B31: 9 | C31: Marketing Plan Development | D31: =VLOOKUP(C31,C7:J26,8,0) -> 7 | E31: =VLOOKUP(C31,C7:K26,9,0) -> 1.3611111 | H31: 39 | I31: =_xlfn.NORM.DIST($K$39,H31,$C$38,TRUE) -> 0.96246901
B32: 10 | C32: Promotional Campaign Execution | D32: =VLOOKUP(C32,C8:J27,8,0) -> 12 | E32: =VLOOKUP(C32,C8:K27,9,0) -> 4.6944444 | H32: 38 | I32: =_xlfn.NORM.DIST($K$39,H32,$C$38,TRUE) -> 0.98108843
B33: 14 | C33: Conference Delivery Day | D33: =VLOOKUP(C33,C9:J28,8,0) -> 1 | E33: =VLOOKUP(C33,C9:K28,9,0) -> 0 | H33: 36 | I33: =_xlfn.NORM.DIST($K$39,H33,$C$38,TRUE) -> 0.99620888
B34: 15 | C34: Post-Event Feedback & Reporting | D34: =VLOOKUP(C34,C10:J29,8,0) -> 5 | E34: =VLOOKUP(C34,C10:K29,9,0) -> 0.69444444
C35: SUM | D35: =SUM(D28:D34) -> 40 | E35: =SUM(E28:E34) -> 11.361111
B37: Expected project duration | C37: =D35 -> 40
B38: project standard deviation | C38: =SQRT(E35) -> 3.3706247
G39: SCHEDULED PROJECT DURATION | K39: 45
B40: chance of this project | C40: =_xlfn.NORM.DIST(K39,C37,C38,TRUE) -> 0.93101652
B42: chance | C42: 0.95
B43: Project Average duration must be | C43: =H31 -> 39

Sheet Scenario 4 Crashing (2)
C4: 0 | E4: =C4+D6 -> 2 | H4: =E4 -> 2 | J4: =H4+I6 -> 7 | L4: =J4 -> 7 | N4: =L4+M6 -> 11 | P4: =N4 -> 11 | R4: =P4+Q6 -> 17
C5: =C6-C4 -> 0 | D5: A | E5: =E6-E4 -> 0 | H5: =H6-H4 -> 1 | I5: B | J5: =J6-J4 -> 1 | L5: =L6-L4 -> 1 | M5: F | N5: =N6-N4 -> 1 | P5: =P6-P4 -> 1 | Q5: G | R5: =R6-R4 -> 1 | AF5: =MAX(AD8,Z8) -> 26 | AH5: =AF5+AG7 -> 27
C6: =E6-D6 -> 0 | D6: 2 | E6: =MIN(H6,H10,H14) -> 2 | H6: =J6-I6 -> 3 | I6: 5 | J6: =MIN(T10,L6) -> 8 | L6: =N6-M6 -> 8 | M6: 4 | N6: =P6 -> 12 | P6: =R6-Q6 -> 12 | Q6: 6 | R6: =AB10 -> 18 | AF6: =AF7-AF5 -> 0 | AG6: N | AH6: =AH7-AH5 -> 0
AF7: =AH7-AG7 -> 26 | AG7: 1 | AH7: =AF13 -> 27
H8: =E4 -> 2 | J8: =H8+I10 -> 6 | P8: =J8 -> 6 | R8: =P8+Q10 -> 11 | T8: =MAX(R8,J4) -> 11 | V8: =T8+U10 -> 17 | X8: =V8 -> 17 | Z8: =X8+Y10 -> 26 | AB8: =MAX(N12,R4,AD12) -> 17 | AD8: =AB8+AC10 -> 25
H9: =H10-H8 -> 0 | I9: C | J9: =J10-J8 -> 0 | P9: =P10-P8 -> 0 | Q9: H | R9: =R10-R8 -> 0 | T9: =T10-T8 -> 0 | U9: I | V9: =V10-V8 -> 0 | X9: =X10-X8 -> 0 | Y9: J | Z9: =Z10-Z8 -> 0 | AB9: =AB10-AB8 -> 1 | AC9: M | AD9: =AD10-AD8 -> 1
H10: =J10-I10 -> 2 | I10: 4 | J10: =P10 -> 6 | P10: =R10-Q10 -> 6 | Q10: 5 | R10: =T10 -> 11 | T10: =V10-U10 -> 11 | U10: 6 | V10: =X10 -> 17 | X10: =Z10-Y10 -> 17 | Y10: 9 | Z10: =AF7 -> 26 | AB10: =AD10-AC10 -> 18 | AC10: 8 | AD10: =AF7 -> 26
AF11: =AH5 -> 27 | AH11: =AF11+AG13 -> 31
H12: =E4 -> 2 | J12: =H12+I14 -> 3 | L12: =J12 -> 3 | N12: =L12+M14 -> 13 | X12: =J12 -> 3 | Z12: =X12+Y14 -> 11 | AB12: =Z12 -> 11 | AD12: =AB12+AC14 -> 16 | AF12: =AF13-AF11 -> 0 | AG12: O | AH12: =AH13-AH11 -> 0
H13: =H14-H12 -> 2 | I13: D | J13: =J14-J12 -> 2 | L13: =L14-L12 -> 5 | M13: E | N13: =N14-N12 -> 5 | X13: =X14-X12 -> 2 | Y13: K | Z13: =Z14-Z12 -> 2 | AB13: =AB14-AB12 -> 2 | AC13: L | AD13: =AD14-AD12 -> 2 | AF13: =AH13-AG13 -> 27 | AG13: 4 | AH13: =AH11 -> 31
H14: =J14-I14 -> 4 | I14: 1 | J14: =MIN(X14,L14) -> 5 | L14: =N14-M14 -> 8 | M14: 10 | N14: =AB10 -> 18 | X14: =Z14-Y14 -> 5 | Y14: 8 | Z14: =AB14 -> 13 | AB14: =AD14-AC14 -> 13 | AC14: 5 | AD14: =AB10 -> 18
Z20: Indirect Cost is | AB20: 90000 | AC20: with | AD20: 4200 | AE20: reduction for one time unit shorten
Z21: Activity ID | AA21: Slope ($) | AB21: Max crash time | AF21: Direct Cost
AF22: Normal | AH22: Crash
AF23: Time | AG23: Cost | AH23: Time | AI23: Cost
Z24: A | AA24: - | AB24: 0 | AF24: ='Scenario 1'!J3 -> t(e) | AG24: 3000 | AH24: 0 | AI24: 0
Z25: B | AA25: 4000 | AB25: 2 | AC25: 1 | AF25: ='Scenario 1'!J4 -> 2 | AG25: 8000 | AH25: 2 | AI25: 4000
Z26: C | AA26: 5000 | AB26: 2 | AC26: 1 | AD26: 0 | AF26: ='Scenario 1'!J5 -> 6 | AG26: 10000 | AH26: 2 | AI26: 5000
Z27: D | AA27: 6000 | AB27: 0 | AF27: ='Scenario 1'!J6 -> 6 | AG27: 18000 | AH27: 3 | AI27: 6000
Z28: E | AA28: 7000 | AB28: 3 | AF28: ='Scenario 1'!J7 -> 8 | AG28: 22000 | AH28: 3 | AI28: 7000
Z29: F | AA29: 3000 | AB29: 1 | AC29: 0 | AF29: ='Scenario 1'!J8 -> 10 | AG29: 6000 | AH29: 1 | AI29: 3000
Z30: G | AA30: 4000 | AB30: 3 | AC30: 2 | AD30: 1 | AE30: 0 | AF30: ='Scenario 1'!J9 -> 5 | AG30: 12000 | AH30: 3 | AI30: 4000
Z31: H | AA31: 6000 | AB31: 2 | AC31: 1 | AD31: 0 | AF31: ='Scenario 1'!J10 -> 9 | AG31: 14000 | AH31: 2 | AI31: 6000
Z32: I | AA32: 4000 | AB32: 1 | AC32: 0 | AF32: ='Scenario 1'!J11 -> 7 | AG32: 9000 | AH32: 1 | AI32: 4000
Z33: J | AA33: 5000 | AB33: 3 | AC33: 2 | AD33: 1 | AE33: 0 | AF33: ='Scenario 1'!J12 -> 7 | AG33: 15000 | AH33: 3 | AI33: 5000
Z34: K | AA34: 4000 | AB34: 2 | AC34: 1 | AF34: ='Scenario 1'!J13 -> 12 | AG34: 11000 | AH34: 2 | AI34: 4000
Z35: L | AA35: 3500 | AB35: 2 | AC35: 1 | AD35: 0 | AF35: ='Scenario 1'!J14 -> 9 | AG35: 8000 | AH35: 2 | AI35: 3500
Z36: M | AA36: 6000 | AB36: 3 | AC36: 2 | AF36: ='Scenario 1'!J15 -> 7 | AG36: 20000 | AH36: 3 | AI36: 6000
Z37: N | AA37: - | AB37: 0 | AF37: ='Scenario 1'!J16 -> 9 | AG37: 30000 | AH37: 0 | AI37: 0
Z38: O | AA38: 2000 | AB38: 1 | AC38: 0 | AF38: ='Scenario 1'!J17 -> 1 | AG38: 6000 | AH38: 1 | AI38: 2000
G41: Path duration
B43: Paths/Iteration | G43: I0 | I43: I1 | K43: I2 | M43: I3 | O43: I4 | Q43: I5 | S43: I6 | U43: I7 | W43: I8 | Y43: I9
B44: ABFGMNO | G44: 37 | I44: 37 | K44: 37 | M44: 37 | O44: 36 | Q44: 35 | S44: 34 | U44: 33 | W44: 32 | Y44: 30
B45: ABIJNO | G45: 33 | I45: 32 | K45: 31 | M45: 30 | O45: 29 | Q45: 29 | S45: 29 | U45: 29 | W45: 28 | Y45: 27
B46: ACHIJNO | G46: 40 | I46: 39 | K46: 38 | M46: 37 | O46: 36 | Q46: 35 | S46: 34 | U46: 33 | W46: 32 | Y46: 31
B47: ADEMNO | G47: 28 | I47: 28 | K47: 28 | M47: 28 | O47: 28 | Q47: 28 | S47: 28 | U47: 28 | W47: 28 | Y47: 26
B48: ADKLMNO | G48: 34 | I48: 34 | K48: 34 | M48: 34 | O48: 34 | Q48: 34 | S48: 34 | U48: 33 | W48: 32 | Y48: 29
Z53: Project duration | AA53: Crashed activities | AB53: Crash cost | AC53: direct cost | AD53: Indirect cost | AE53: Total cost
Y54: I0 | Z54: 40 | AA54: - | AB54: - | AC54: =SUM(AG24:AG38) -> 192000 | AD54: =AB20 -> 90000 | AE54: =AC54+AD54 -> 282000
Y55: I1 | Z55: 39 | AA55: I | AB55: =AA32 -> 4000 | AC55: =AC54+AB55 -> 196000 | AD55: =AD54-$AD$20 -> 85800 | AE55: =AC55+AD55 -> 281800
...

Sheet Scenario 5
B3: Activity code | C3: Activity description | D3: predecessors | F3: Activity code | G3: optimistic | H3: Most likely | I3: Pessimistic | J3: t(e) | K3: variance | L3: Critical Path
B4: 1 (A) | C4: Initial Project Kick-Off | D4: - | F4: 1 | G4: 1 | H4: 2 | I4: 3 | J4: =ROUND((G4+4*H4+I4)/6,0) -> 2 | K4: =((I4-G4)/6)^2 -> 0.11111111 | L4: ✓ | O4: 0 | Q4: =O4+P6 -> 2 | T4: =Q4 -> 2 | V4: =T4+U6 -> 8 | X4: =V4 -> 8 | Z4: =X4+Y6 -> 13 | AB4: =Z4 -> 13 | AD4: =AB4+AC6 -> 22
B5: 2 (B) | C5: Define Conference Themes & Tracks | D5: 1 | F5: 2 | G5: 4 | H5: 6 | I5: 10 | J5: =ROUND((G5+4*H5+I5)/6,0) -> 6 | K5: =((I5-G5)/6)^2 -> 1 | O5: =O6-O4 -> 0 | P5: A | Q5: =Q6-Q4 -> 0 | T5: =T6-T4 -> 3 | U5: B | V5: =V6-V4 -> 3 | X5: =X6-X4 -> 3 | Y5: F | Z5: =Z6-Z4 -> 3 | AB5: =AB6-AB4 -> 3 | AC5: G | AD5: =AD6-AD4 -> 3 | AR5: =MAX(AP8,AL8) -> 34 | AT5: =AR5+AS7 -> 35
B6: 3 (C ) | C6: Keynote Speaker Identification | D6: 1 | F6: 3 | G6: 3 | H6: 6 | I6: 12 | J6: =FLOOR((G6+4*H6+I6)/6,1) -> 6 | K6: =((I6-G6)/6)^2 -> 2.25 | L6: ✓ | O6: =Q6-P6 -> 0 | P6: =J4 -> 2 | Q6: =MIN(T6,T10,T14) -> 2 | T6: =V6-U6 -> 5 | U6: =J5 -> 6 | V6: =MIN(AF10,X6) -> 11 | X6: =Z6-Y6 -> 11 | Y6: =J9 -> 5 | Z6: =AB6 -> 16 | AB6: =AD6-AC6 -> 16 | AC6: =J10 -> 9 | AD6: =AN10 -> 25 | AR6: =AR7-AR5 -> 0 | AS6: N | AT6: =AT7-AT5 -> 0
B7: 4 (D) | C7: Venue Booking & Contracting | D7: 1 | F7: 4 | G7: 0 | H7: 1 | I7: 2 | J7: =FLOOR((G7+4*H7+I7)/6,1) -> 1 | K7: =((I7-G7)/6)^2 -> 0.11111111 | AR7: =AT7-AS7 -> 34 | AS7: 1 | AT7: =AR13 -> 35
B8: 5 (E ) | C8: Hybrid Technical Setup | D8: 4 | F8: 5 | G8: 6 | H8: 10 | I8: 16 | J8: =ROUND((G8+4*H8+I8)/6,0) -> 10 | K8: =((I8-G8)/6)^2 -> 2.7777778 | T8: =Q4 -> 2 | V8: =T8+U10 -> 8 | AB8: =V8 -> 8 | AD8: =AB8+AC10 -> 15 | AF8: =MAX(AD8,V4) -> 15 | AH8: =AF8+AG10 -> 22 | AJ8: =AH8 -> 22 | AL8: =AJ8+AK10 -> 34 | AN8: =MAX(Z12,AD4,AP12) -> 22 | AP8: =AN8+AO10 -> 31
B9: 6 (F) | C9: Sponsorship Package Development | D9: 2 | F9: 6 | G9: 3 | H9: 5 | I9: 9 | J9: =ROUND((G9+4*H9+I9)/6,0) -> 5 | K9: =((I9-G9)/6)^2 -> 1 | T9: =T10-T8 -> 0 | U9: C | V9: =V10-V8 -> 0 | AB9: =AB10-AB8 -> 0 | AC9: H | AD9: =AD10-AD8 -> 0 | AF9: =AF10-AF8 -> 0 | AG9: I | AH9: =AH10-AH8 -> 0 | AJ9: =AJ10-AJ8 -> 0 | AK9: J | AL9: =AL10-AL8 -> 0 | AN9: =AN10-AN8 -> 3 | AO9: M | AP9: =AP10-AP8 -> 3
B10: 7 (G) | C10: Sponsor Outreach & Negotiation | D10: 6 | F10: 7 | G10: 5 | H10: 9 | I10: 18 | J10: =FLOOR((G10+4*H10+I10)/6,1) -> 9 | K10: =((I10-G10)/6)^2 -> 4.6944444 | T10: =V10-U10 -> 2 | U10: =J6 -> 6 | V10: =AB10 -> 8 | AB10: =AD10-AC10 -> 8 | AC10: =J11 -> 7 | AD10: =AF10 -> 15 | AF10: =AH10-AG10 -> 15 | AG10: =J12 -> 7 | AH10: =AJ10 -> 22 | AJ10: =AL10-AK10 -> 22 | AK10: =J13 -> 12 | AL10: =AR7 -> 34 | AN10: =AP10-AO10 -> 25 | AO10: =J16 -> 9 | AP10: =AR7 -> 34
B11: 8 (H) | C11: Keynote Speaker Confirmation | D11: 3 | F11: 8 | G11: 4 | H11: 7 | I11: 13 | J11: =FLOOR((G11+4*H11+I11)/6,1) -> 7 | K11: =((I11-G11)/6)^2 -> 2.25 | L11: ✓ | AR11: =AT5 -> 35 | AT11: =AR11+AS13 -> 40
B12: 9 (I) | C12: Marketing Plan Development | D12: 2, 8 | F12: 9 | G12: 4 | H12: 7 | I12: 11 | J12: =ROUND((G12+4*H12+I12)/6,0) -> 7 | K12: =((I12-G12)/6)^2 -> 1.3611111 | L12: ✓ | T12: =Q4 -> 2 | V12: =T12+U14 -> 3 | X12: =V12 -> 3 | Z12: =X12+Y14 -> 13 | AJ12: =V12 -> 3 | AL12: =AJ12+AK14 -> 12 | AN12: =AL12 -> 12 | AP12: =AN12+AO14 -> 19 | AR12: =AR13-AR11 -> 0 | AS12: 15 | AT12: =AT13-AT11 -> 0
B13: 10( J) | C13: Promotional Campaign Execution | D13: 9 | F13: 10 | G13: 7 | H13: 12 | I13: 20 | J13: =FLOOR((G13+4*H13+I13)/6,1) -> 12 | K13: =((I13-G13)/6)^2 -> 4.6944444 | L13: ✓ | T13: =T14-T12 -> 6 | U13: D | V13: =V14-V12 -> 6 | X13: =X14-X12 -> 12 | Y13: E | Z13: =Z14-Z12 -> 12 | AJ13: =AJ14-AJ12 -> 6 | AK13: K | AL13: =AL14-AL12 -> 6 | AN13: =AN14-AN12 -> 6 | AO13: L | AP13: =AP14-AP12 -> 6 | AR13: =AT13-AS13 -> 35 | AS13: 5 | AT13: =AT11 -> 40
B14: 11 (K) | C14: Catering & Layout Planning | D14: 4 | F14: 11 | G14: 6 | H14: 9 | I14: 14 | J14: =ROUND((G14+4*H14+I14)/6,0) -> 9 | K14: =((I14-G14)/6)^2 -> 1.7777778 | T14: =V14-U14 -> 8 | U14: =J7 -> 1 | V14: =MIN(AJ14,X14) -> 9 | X14: =Z14-Y14 -> 15 | Y14: =J8 -> 10 | Z14: =AN10 -> 25 | AJ14: =AL14-AK14 -> 9 | AK14: =J14 -> 9 | AL14: =AN14 -> 18 | AN14: =AP14-AO14 -> 18 | AO14: =J15 -> 7 | AP14: =AN10 -> 25
B15: 12 (L) | C15: Volunteer Recruitment & Training | D15: 11 | F15: 12 | G15: 4 | H15: 7 | I15: 13 | J15: =FLOOR((G15+4*H15+I15)/6,1) -> 7 | K15: =((I15-G15)/6)^2 -> 2.25
B16: 13 (M) | C16: On-Site Logistics Preparation | D16: 5, 7, 12 | F16: 13 | G16: 5 | H16: 9 | I16: 15 | J16: =ROUND((G16+4*H16+I16)/6,0) -> 9 | K16: =((I16-G16)/6)^2 -> 2.7777778
B17: 14 (N) | C17: Conference Delivery Day | D17: 13, 10 | F17: 14 | G17: 1 | H17: 1 | I17: 1 | J17: =ROUND((G17+4*H17+I17)/6,0) -> 1 | K17: =((I17-G17)/6)^2 -> 0 | L17: ✓
B18: 15 (O) | C18: Post-Event Feedback & Reporting | D18: 14 | F18: 15 | G18: 3 | H18: 5 | I18: 8 | J18: =ROUND((G18+4*H18+I18)/6,0) -> 5 | K18: =((I18-G18)/6)^2 -> 0.69444444 | L18: ✓
H25: Mean | I25: Probability
H26: 44 | I26: =_xlfn.NORM.DIST($K$39,H26,$C$38,TRUE) -> 0.61664493
B27: Activity Code | C27: critical activities | D27: tc(e) | E27: variance | H27: 43 | I27: =_xlfn.NORM.DIST($K$39,H27,$C$38,TRUE) -> 0.72353048
B28: 1 | C28: Initial Project Kick-Off | D28: =VLOOKUP(C28,C4:J18,8,0) -> 2 | E28: =VLOOKUP(C28,C4:K18,9,0) -> 0.11111111 | H28: 42 | I28: =_xlfn.NORM.DIST($K$39,H28,$C$38,TRUE) -> 0.81327853
B29: 3 | C29: Keynote Speaker Identification | D29: =VLOOKUP(C29,C5:J19,8,0) -> 6 | E29: =VLOOKUP(C29,C5:K19,9,0) -> 2.25 | H29: 41 | I29: =_xlfn.NORM.DIST($K$39,H29,$C$38,TRUE) -> 0.88233167
B30: 8 | C30: Keynote Speaker Confirmation | D30: =VLOOKUP(C30,C6:J25,8,0) -> 7 | E30: =VLOOKUP(C30,C6:K25,9,0) -> 2.25 | H30: 40 | I30: =_xlfn.NORM.DIST($K$39,H30,$C$38,TRUE) -> 0.93101652
B31: 9 | C31: Marketing Plan Development | D31: =VLOOKUP(C31,C7:J26,8,0) -> 7 | E31: =VLOOKUP(C31,C7:K26,9,0) -> 1.3611111 | H31: 39 | I31: =_xlfn.NORM.DIST($K$39,H31,$C$38,TRUE) -> 0.96246901
B32: 10 | C32: Promotional Campaign Execution | D32: =VLOOKUP(C32,C8:J27,8,0) -> 12 | E32: =VLOOKUP(C32,C8:K27,9,0) -> 4.6944444 | H32: 38 | I32: =_xlfn.NORM.DIST($K$39,H32,$C$38,TRUE) -> 0.98108843
B33: 14 | C33: Conference Delivery Day | D33: =VLOOKUP(C33,C9:J28,8,0) -> 1 | E33: =VLOOKUP(C33,C9:K28,9,0) -> 0 | H33: 36 | I33: =_xlfn.NORM.DIST($K$39,H33,$C$38,TRUE) -> 0.99620888
B34: 15 | C34: Post-Event Feedback & Reporting | D34: =VLOOKUP(C34,C10:J29,8,0) -> 5 | E34: =VLOOKUP(C34,C10:K29,9,0) -> 0.69444444
C35: SUM | D35: =SUM(D28:D34) -> 40 | E35: =SUM(E28:E34) -> 11.361111
B37: Expected project duration | C37: =D35 -> 40
B38: project standard deviation | C38: =SQRT(E35) -> 3.3706247
G39: SCHEDULED PROJECT DURATION | K39: 45
B40: chance of this project | C40: =_xlfn.NORM.DIST(K39,C37,C38,TRUE) -> 0.93101652
B42: chance | C42: 0.95
B43: Project Average duration must be | C43: =H31 -> 39

Sheet Scenario 5 Crashing
C4: 0 | E4: =C4+D6 -> 2 | H4: =E4 -> 2 | J4: =H4+I6 -> 6 | L4: =J4 -> 6 | N4: =L4+M6 -> 10 | P4: =N4 -> 10 | R4: =P4+Q6 -> 16
C5: =C6-C4 -> 0 | D5: A | E5: =E6-E4 -> 0 | H5: =H6-H4 -> 1 | I5: B | J5: =J6-J4 -> 1 | L5: =L6-L4 -> 1 | M5: F | N5: =N6-N4 -> 1 | P5: =P6-P4 -> 1 | Q5: G | R5: =R6-R4 -> 1 | AF5: =MAX(AD8,Z8) -> 23 | AH5: =AF5+AG7 -> 24
C6: =E6-D6 -> 0 | D6: 2 | E6: =MIN(H6,H10,H14) -> 2 | H6: =J6-I6 -> 3 | I6: 4 | J6: =MIN(T10,L6) -> 7 | L6: =N6-M6 -> 7 | M6: 4 | N6: =P6 -> 11 | P6: =R6-Q6 -> 11 | Q6: 6 | R6: =AB10 -> 17 | AF6: =AF7-AF5 -> 0 | AG6: N | AH6: =AH7-AH5 -> 0
AF7: =AH7-AG7 -> 23 | AG7: 1 | AH7: =AF13 -> 24
H8: =E4 -> 2 | J8: =H8+I10 -> 6 | P8: =J8 -> 6 | R8: =P8+Q10 -> 8 | T8: =MAX(R8,J4) -> 8 | V8: =T8+U10 -> 14 | X8: =V8 -> 14 | Z8: =X8+Y10 -> 23 | AB8: =MAX(N12,R4,AD12) -> 16 | AD8: =AB8+AC10 -> 22
H9: =H10-H8 -> 0 | I9: C | J9: =J10-J8 -> 0 | P9: =P10-P8 -> 0 | Q9: H | R9: =R10-R8 -> 0 | T9: =T10-T8 -> 0 | U9: I | V9: =V10-V8 -> 0 | X9: =X10-X8 -> 0 | Y9: J | Z9: =Z10-Z8 -> 0 | AB9: =AB10-AB8 -> 1 | AC9: M | AD9: =AD10-AD8 -> 1
H10: =J10-I10 -> 2 | I10: 4 | J10: =P10 -> 6 | P10: =R10-Q10 -> 6 | Q10: 2 | R10: =T10 -> 8 | T10: =V10-U10 -> 8 | U10: 6 | V10: =X10 -> 14 | X10: =Z10-Y10 -> 14 | Y10: 9 | Z10: =AF7 -> 23 | AB10: =AD10-AC10 -> 17 | AC10: 6 | AD10: =AF7 -> 23
AF11: =AH5 -> 24 | AH11: =AF11+AG13 -> 28
H12: =E4 -> 2 | J12: =H12+I14 -> 3 | L12: =J12 -> 3 | N12: =L12+M14 -> 13 | X12: =J12 -> 3 | Z12: =X12+Y14 -> 10 | AB12: =Z12 -> 10 | AD12: =AB12+AC14 -> 15 | AF12: =AF13-AF11 -> 0 | AG12: O | AH12: =AH13-AH11 -> 0
H13: =H14-H12 -> 2 | I13: D | J13: =J14-J12 -> 2 | L13: =L14-L12 -> 4 | M13: E | N13: =N14-N12 -> 4 | X13: =X14-X12 -> 2 | Y13: K | Z13: =Z14-Z12 -> 2 | AB13: =AB14-AB12 -> 2 | AC13: L | AD13: =AD14-AD12 -> 2 | AF13: =AH13-AG13 -> 24 | AG13: 4 | AH13: =AH11 -> 28
H14: =J14-I14 -> 4 | I14: 1 | J14: =MIN(X14,L14) -> 5 | L14: =N14-M14 -> 7 | M14: 10 | N14: =AB10 -> 17 | X14: =Z14-Y14 -> 5 | Y14: 7 | Z14: =AB14 -> 12 | AB14: =AD14-AC14 -> 12 | AC14: 5 | AD14: =AB10 -> 17
Z20: Indirect Cost is | AB20: 90000 | AC20: with | AD20: 4200 | AE20: reduction for one time unit shorten
Z21: Activity ID | AA21: Slope ($) | AB21: Max crash time | AH21: Direct Cost
AH22: Normal | AJ22: Crash
AH23: Time | AI23: Cost | AJ23: Time | AK23: Cost
Z24: A | AA24: - | AB24: 0 | AH24: ='Scenario 1'!J3 -> t(e) | AI24: 3000 | AJ24: 0 | AK24: 0
Z25: B | AA25: 4000 | AB25: 2 | AC25: 1 | AD25: 0 | AH25: ='Scenario 1'!J4 -> 2 | AI25: 8000 | AJ25: 2 | AK25: 4000
Z26: C | AA26: 5000 | AB26: 2 | AC26: 1 | AD26: 0 | AH26: ='Scenario 1'!J5 -> 6 | AI26: 10000 | AJ26: 2 | AK26: 5000
Z27: D | AA27: 6000 | AB27: 0 | AH27: ='Scenario 1'!J6 -> 6 | AI27: 18000 | AJ27: 3 | AK27: 6000
Z28: E | AA28: 7000 | AB28: 3 | AH28: ='Scenario 1'!J7 -> 8 | AI28: 22000 | AJ28: 3 | AK28: 7000
Z29: F | AA29: 3000 | AB29: 1 | AC29: 0 | AH29: ='Scenario 1'!J8 -> 10 | AI29: 6000 | AJ29: 1 | AK29: 3000
Z30: G | AA30: 4000 | AB30: 3 | AC30: 2 | AD30: 1 | AE30: 0 | AH30: ='Scenario 1'!J9 -> 5 | AI30: 12000 | AJ30: 3 | AK30: 4000
Z31: H | AA31: 6000 | AB31: 5 | AC31: 4 | AD31: 3 | AE31: 2 | AF31: 1 | AG31: 0 | AH31: ='Scenario 1'!J10 -> 9 | AI31: 14000 | AJ31: 2 | AK31: 6000
Z32: I | AA32: 4000 | AB32: 1 | AC32: 0 | AH32: ='Scenario 1'!J11 -> 7 | AI32: 9000 | AJ32: 1 | AK32: 4000
Z33: J | AA33: 5000 | AB33: 3 | AC33: 2 | AD33: 1 | AE33: 0 | AH33: ='Scenario 1'!J12 -> 7 | AI33: 15000 | AJ33: 3 | AK33: 5000
Z34: K | AA34: 4000 | AB34: 2 | AC34: 1 | AD34: 0 | AH34: ='Scenario 1'!J13 -> 12 | AI34: 11000 | AJ34: 2 | AK34: 4000
Z35: L | AA35: 3500 | AB35: 2 | AC35: 1 | AD35: 0 | AH35: ='Scenario 1'!J14 -> 9 | AI35: 8000 | AJ35: 2 | AK35: 3500
Z36: M | AA36: 6000 | AB36: 3 | AC36: 2 | AD36: 1 | AE36: 0 | AH36: ='Scenario 1'!J15 -> 7 | AI36: 20000 | AJ36: 3 | AK36: 6000
Z37: N | AA37: - | AB37: 0 | AH37: ='Scenario 1'!J16 -> 9 | AI37: 30000 | AJ37: 0 | AK37: 0
Z38: O | AA38: 2000 | AB38: 1 | AC38: 0 | AH38: ='Scenario 1'!J17 -> 1 | AI38: 6000 | AJ38: 1 | AK38: 2000
G41: Path duration
B43: Paths/Iteration | G43: I0 | I43: I1 | K43: I2 | M43: I3 | O43: I4 | Q43: I5 | S43: I6 | U43: I7 | W43: I8 | Y43: I9 | AA43: I10 | AC43: I11 | AE43: I12 | AG43: I13
B44: ABFGMNO | G44: 37 | I44: 36 | K44: 36 | M44: 36 | O44: 36 | Q44: 35 | S44: 34 | U44: 33 | W44: 32 | Y44: 31 | AA44: 30 | AC44: 29 | AE44: 28 | AG44: =$D$6+$I$6+$M$6+$Q$6+$AC$10+$AG$7+$AG$13 -> 27
B45: ABIJNO | G45: 33 | I45: 32 | K45: 31 | M45: 30 | O45: 29 | Q45: 28 | S45: 28 | U45: 28 | W45: 28 | Y45: 27 | AA45: 26 | AC45: 26 | AE45: 26 | AG45: =$D$6+$I$6+$U$10+$Y$10+$AG$7+$AG$13 -> 26
B46: ACHIJNO | G46: 40 | I46: 39 | K46: 38 | M46: 37 | O46: 36 | Q46: 35 | S46: 34 | U46: 33 | W46: 32 | Y46: 31 | AA46: 30 | AC46: 29 | AE46: 28 | AG46: =$D$6+$I$10+$Q$10+$U$10+$Y$10+$AG$7+$AG$13 -> 28
B47: ADEMNO | G47: 28 | I47: 27 | K47: 27 | M47: 27 | O47: 27 | Q47: 27 | S47: 27 | U47: 27 | W47: 27 | Y47: 27 | AA47: 27 | AC47: 26 | AE47: 25 | AG47: =$D$6+$I$14+$M$14+$AC$10+$AG$7+$AG$13 -> 24
B48: ADKLMNO | G48: 34 | I48: 33 | K48: 33 | M48: 33 | O48: 33 | Q48: 33 | S48: 33 | U48: 33 | W48: 32 | Y48: 31 | AA48: 30 | AC48: 28 | AE48: 27 | AG48: =$D$6+$I$14+$Y$14+$AC$14+$AC$10+$AG$7+$AG$13 -> 26
Z53: Project duration | AA53: Crashed activities | AB53: Crash cost | AC53: direct cost | AD53: Indirect cost | AE53: Total cost
Y54: I0 | Z54: 40 | AA54: - | AB54: - | AC54: =SUM(AI24:AI38) -> 192000 | AD54: =AB20 -> 90000 | AE54: =AC54+AD54 -> 282000
Y55: I1 | Z55: 39 | AA55: O | AB55: =AA38 -> 2000 | AC55: =AC54+AB55 -> 194000 | AD55: =AD54-$AD$20 -> 85800 | AE55: =AC55+AD55 -> 279800
...
